Workbook

Sheet RA-001
A1: Saudi Search & Rescue team فريق البحث والإنقاذ السعودي | L1: LEGEND
L2: R : RESCUE | N2: RA001-A
L3: A : ALPHA | N3: RA001-A
L4: 001 : BOX NUMBER | N4: RA001-A
L5: A : ITEM NUMBER | N5: RA001-A
A6: RESCUE ALPHA
A7: BOX NUMBER RA-001
A8: S/N | B8: ITEM NUMBER | C8: MAIN ITEM DESCRIPTION | E8: SUB-ITEM | J8: PRICE (SR) | L8: REMARKS
E9: DESCRIPTION | H9: SUB-ITEM NUMBER | I9: QTY
J10: SAR | K10: USD
A11: 1 | B11: RA001-A | C11: Ladder سلم | I11: 1 | J11: 50 | K11: =SUM(J11/3.75) -> 13.333333
A12: 2 | B12: RA001-B | C12: Chairs كراسي | I12: 2 | J12: 140 | K12: =SUM(J12/3.75) -> 37.333333
A13: 3 | B13: RA001-C | C13: Siren اداة نداء يدوية | I13: 1 | J13: 2769 | K13: =SUM(J13/3.75) -> 738.4
A14: 4 | B14: RA001-D | C14: Safety jacket سترة السلامة | I14: 1 | J14: 146 | K14: =SUM(J14/3.75) -> 38.933333
A15: 5 | B15: RA001-E | C15: Waste basket سلة نفايات | I15: 1 | J15: 15 | K15: =SUM(J15/3.75) -> 4
A16: 6 | B16: RA001-F | C16: GROUND SHEET حنبل | I16: 1 | J16: 25 | K16: =SUM(J16/3.75) -> 6.6666667
A17: 7 | B17: RA001-G | C17: A.C hotstick عصا كشف الكهرباء | I17: 1 | J17: 4670 | K17: =SUM(J17/3.75) -> 1245.3333
A18: 8 | B18: RA001-H | C18: Wall Hanging Packet علاقة حائط بجيبوب | I18: 1 | J18: 236 | K18: =SUM(J18/3.75) -> 62.933333
A19: 9 | B19: RA001-I | C19: died Body bags اكياس موتى | I19: 7 | J19: 600 | K19: =SUM(J19/3.75) -> 160
A20: 10 | B20: RA001-J | C20: Face Mask كمام N95 | I20: 40 | J20: 152 | K20: =SUM(J20/3.75) -> 40.533333
A21: 11 | B21: RA001-K | C21: Cleaning Brush فرشاة تنظيف | I21: 1 | J21: 5 | K21: =SUM(J21/3.75) -> 1.3333333
A22: 12 | B22: RA001-L | C22: Spade كريك | I22: 1 | J22: 50 | K22: =SUM(J22/3.75) -> 13.333333
... A25: 15 | B25: RA001-O | C25: Light إضاءة كشاف | I25: 1 | J25: 500 | K25: =SUM(J25/3.75) -> 133.33333
A26: 16 | B26: RA001-P | C26: Spray Paint بخاخ تلوين | I26: 4 | J26: 40 | K26: =SUM(J26/3.75) -> 10.666667 | L26: UN 1950
A27: 17 | B27: RA001-Q | C27: Tool box صندوق عدة | I27: 1 | J27: 2415 | K27: =SUM(J27/3.75) -> 644
A28: 18 | B28: RA001-R | C28: Foldable water Bag جركل ماء قابل للطي | I28: 1 | J28: 150 | K28: =SUM(J28/3.75) -> 40
A29: 19 | B29: RA001-S | C29: GLASS BREAKING اداء لقطع الاحزمة وكسر الزجاج | I29: 1 | J29: 300 | K29: 80
A30: 20 | B30: RA001-T | C30: White board سبورة بيضاء +مساحه+اقلام | I30: 1 | J30: 750 | K30: =SUM(J30/3.75) -> 200
A31: 21 | B31: RA001-U | C31: STANDING SITE NAMES استاند مسميات مواقع | I31: 3 | J31: 120 | K31: =SUM(J31/3.75) -> 32
A32: 22 | B32: RA001-V | C32: YELLOW WARNING SIGN اشارة تحذيرية لون اصفر | I32: 1 | J32: 80 | K32: =SUM(J32/3.75) -> 21.333333
A33: 23 | B33: RA001-W | C33: SAFETY GREEN -BIUE-WHITE-RED سفتي لون اخضر- ازرق ابيض-احمر- | I33: 4 | J33: 50 | K33: =SUM(J33/3.75) -> 13.333333
A34: 24 | B34: RA001-X | C34: W.C دورة مياة | I34: 1 | J34: 3000 | K34: =SUM(J34/3.75) -> 800
A35: 25 | B35: RA001-Y | C35: Chair كرسي | I35: 1 | J35: 100 | K35: =SUM(J35/3.75) -> 26.666667
A36: 26 | B36: RA001-Z | C36: Personal trash bags أكياس نفايات شخصية | I36: 30 | J36: 300 | K36: =SUM(J36/3.75) -> 80
A37: 27 | B37: RA001-AB | C37: A WARNING LIGHT FIXTURE عامود تثبيت انارة تحذيرية | I37: 2 | J37: 50 | K37: =SUM(J37/3.75) -> 13.333333
A39: Last up Date | B39: Taken Over By | D39: Handed Over By | F39: L×W×H | I39: Total | K39: Total Weight | M39: Total Price
A40: =TODAY() -> 46198 | B40: Mishary Al Marzouki | D40: abdulrhman Al-marhabi | F40: Cm | G40: Inch | I40: CBM | J40: CFT | K40: KG | L40: LBS | M40: SAR | N40: USD
F41: 130×70×65 | G41: 51.18×27.56×25.59 | I41: =SUM(130*70*65/1000000) -> 0.5915 | J41: =SUM(51.18*27.56*25.59/1728) -> 20.888442 | K41: 140 | L41: =SUM(K41*2.2) -> 308 | M41: =SUM(J11:J37) -> 16793 | N41: =SUM(M41/3.75) -> 4478.1333

Sheet RA-002
A1: Saudi Search & Rescue team فريق البحث والإنقاذ السعودي | L1: LEGEND
L2: R : RESCUE | N2: RA002-A
L3: A : ALPHA | N3: RA002-A
L4: 002 : BOX NUMBER | N4: RA002-A
L5: A : ITEM NUMBER | N5: RA002-A
A6: RESCUE ALPHA
A7: BOX NUMBER RA-002
A8: S/N | B8: ITEM NUMBER | C8: MAIN ITEM DESCRIPTION | E8: SUB-ITEM | J8: PRICE (SR) | L8: REMARKS
E9: DESCRIPTION | H9: SUB-ITEM NUMBER | I9: QTY
J10: SAR | K10: USD
A11: 1 | B11: RA002-A | C11: Red Way Extension توصيلة كهرباء حمراء | I11: 2 | J11: 250 | K11: =SUM(J11/3.75) -> 66.666667
A15: 2 | B15: RA002-B | C15: Fire Extinguisher طفاية | I15: 1 | J15: 58 | K15: =SUM(J15/3.75) -> 15.466667 | L15: UN1044
A17: 3 | B17: RA002-C | C17: Air cylinder اسطوانة هواء عادي | I17: 6 | J17: 9120 | K17: =SUM(J17/3.75) -> 2432 | L17: UN1002
A19: 4 | B19: RA002-D | C19: Wire Extension عازل توصيلة كهرباء | I19: 3 | J19: 300 | K19: =SUM(J19/3.75) -> 80
A21: 5 | B21: RA002-E | C21: Electric Extension توصيلة كهرباء ألمنيوم | I21: 1 | J21: 300 | K21: =SUM(J21/3.75) -> 80
A23: 6 | B23: RA002-F | C23: Honda Generator مولد هوندا أحمر | I23: 1 | J23: 7485 | K23: =SUM(J23/3.75) -> 1996 | L23: UN3528
A25: 7 | B25: RA002-C | C25: منفاخ خيمة الاستراحه | I25: 1 | J25: 300 | K25: =SUM(J25/3.75) -> 80
A28: Last up Date | B28: Taken Over By | D28: Handed Over By | F28: L×W×H | I28: Total | K28: Total Weight | M28: Total Price
A29: =TODAY() -> 46198 | B29: Mishary Al Marzouki | D29: abdulrhman Al-marhabi | F29: Cm | G29: Inch | I29: CBM | J29: CFT | K29: KG | L29: LBS | M29: SAR | N29: USD
F30: 130×70×65 | G30: 51.18×27.56×25.59 | I30: =SUM(130*70*65/1000000) -> 0.5915 | J30: =SUM(51.18*27.56*25.59/1728) -> 20.888442 | K30: 122 | L30: =SUM(K30*2.2) -> 268.4 | M30: =SUM(J11:J25) -> 17813 | N30: =SUM(M30/3.75) -> 4750.1333

Sheet RA-003
A1: Saudi Search & Rescue team فريق البحث والإنقاذ السعودي | L1: LEGEND
L2: R : RESCUE | N2: RA003-A
L3: A : ALPHA | N3: RA003-A
L4: 003 : BOX NUMBER | N4: RA003-A
L5: A : ITEM NUMBER | N5: RA003-A
A6: RESCUE ALPHA
A7: BOX NUMBER RA-003
A8: S/N | B8: ITEM NUMBER | C8: MAIN ITEM DESCRIPTION | E8: SUB-ITEM | J8: PRICE (SR) | L8: REMARKS
E9: DESCRIPTION | H9: SUB-ITEM NUMBER | I9: QTY
J10: SAR | K10: USD
A11: 1 | B11: RA003-A | C11: Air Ventilator + Duct مروحة شفط كهربائية + خرطوش | I11: 1 | J11: 3805 | K11: =SUM(J11/3.75) -> 1014.6667
A13: 2 | B13: RA003-B | C13: HAMMER مطرقة | I13: 2 | J13: 20 | K13: =SUM(J13/3.75) -> 5.3333333
A15: 3 | B15: RA003-C | C15: Bolt cutter مقص يدوي حديد- كهرب | I15: 1 | J15: 180 | K15: =SUM(J15/3.75) -> 48
A17: 4 | B17: RA003-D | C17: Air bag وسادة هوائية | E17: وسط / صغير medium / small | H17: RA003-D1 | I17: 2 | J17: 1231 | K17: =SUM(J17/3.75) -> 328.26667
A19: 5 | B19: RA003-E | C19: Air bag set وسائد هوائية مربعة | E19: Regulator ساعة منظم | H19: RA003-E1 | I19: 1 | J19: 3521 | K19: =SUM(J19/3.75) -> 938.93333
E20: Hose ليات توصيل | H20: RA003-E2 | I20: 2
E21: Main controller yellow موزع جهاز التحكم (برتقالي) | H21: RA003-E3 | I21: 1
A23: Last up Date | B23: Taken Over By | D23: Handed Over By | F23: L×W×H | I23: Total | K23: Total Weight | M23: Total Price
A24: =TODAY() -> 46198 | B24: Mishary Al Marzouki | D24: abdulrhman Al-marhabi | F24: Cm | G24: Inch | I24: CBM | J24: CFT | K24: KG | L24: LBS | M24: SAR | N24: USD
F25: 130×70×65 | G25: 51.18×27.56×25.59 | I25: =SUM(130*70*65/1000000) -> 0.5915 | J25: =SUM(51.18*27.56*25.59/1728) -> 20.888442 | K25: 103 | L25: =SUM(K25*2.2) -> 226.6 | M25: =SUM(J11:J21) -> 8757 | N25: =SUM(M25/3.75) -> 2335.2

Sheet عربة 4
A1: Saudi Search & Rescue team فريق البحث والإنقاذ السعودي | L1: LEGEND
L2: R : RESCUE | N2: RA004-A
L3: A : ALPHA | N3: RA004-A
L4: 004 :TROLLEY NUMBER | N4: RA004-A
L5: A : ITEM NUMBER | N5: RA004-A
A6: RESCUE ALPHA
A7: TROLLEY NUMBER RA-004
A8: S/N | B8: ITEM NUMBER | C8: MAIN ITEM DESCRIPTION | E8: SUB-ITEM | J8: PRICE (SR) | L8: REMARKS
E9: DESCRIPTION | H9: SUB-ITEM NUMBER | I9: QTY
J10: SAR | K10: USD
A11: 1 | B11: RA-004-A | C11: Holmatro Hand Pump Set مضخة هيدروليكية يدوية | E11: وصلات Connections | G11: صغير small | H11: RA-004A1 | I11: 1 | J11: 800 | K11: =SUM(J11/3.75) -> 213.33333
G12: وسط medium | I12: 1
G13: كبير big | I13: 1
E14: Rigid Base قاعدة ثابته | H14: RA-004A2 | I14: 2
E15: قسام Distributor | G15: ذكر male | H15: RA-004A3 | I15: 3
G16: أنثى female | I16: 2
E17: heads رؤوس | G17: مدبب Taprred | H17: RA-004A4 | I17: 2
G18: flat مسطح | I18: 2
G19: راس مخروط CONE HEAD | H19: RA-004A5 | I19: 1
G20: نهاية راس HEAD END | I20: 2
E21: Hand pumb مضخة يدوية | H21: RA-004A6 | I21: 1
E22: Hand jack عفريتة | G22: small صغير | H22: RA-004A7 | I22: 1
G23: medium وسط | I23: 1
E24: Small Spreader فالج صفير | H24: RA-004A8 | I24: 1
A25: 2 | B25: RA004-B | C25: Prying Tool معدات الدخول القهري | I25: 1 | J25: 6500 | K25: 1733.3333
A26: 3 | B26: RA004-C | C26: Wire Pulling machine ونش سحب | I26: 1 | J26: 2000 | K26: 533
A27: 4 | B27: RA004-D | C27: Pullling cable واير سحب | I27: 1 | J27: 231 | K27: =SUM(J27/3.75) -> 61.6
A28: 5 | B28: RA004-E | C28: Chrome Bow Shackle هوك سحـب | I28: 5 | J28: 250 | K28: =SUM(J28/3.75) -> 66.666667
A29: 6 | B29: RA004-F | C29: iron chain سلسلة حديد | I29: 1 | J29: 1100 | K29: =SUM(J29/3.75) -> 293.33333
A30: 7 | B30: RA004-G | C30: Ground sheet حنبل | I30: 1 | J30: 25 | K30: 7
A31: 8 | B31: RA004-H | C31: سبت سحب بني كبير Large brown webbing | I31: 4 | J31: 280 | K31: 74.666667
A32: 9 | B32: RA004-I | C32: Gray webbing سبت سحب ( فضي ) وسط | I32: 4 | J32: 280 | K32: 74.666667
A35: Last up Date | B35: Taken Over By | D35: Handed Over By | F35: L×W×H | I35: Total | K35: Total Weight | M35: Total Price
A36: =TODAY() -> 46198 | B36: Abdulrahman Al-Shakrah | D36: abdulrhman Al-marhabi | F36: Cm | G36: Inch | I36: CBM | J36: CFT | K36: KG | L36: LBS | M36: SAR | N36: USD
F37: 130×70×65 | G37: 51.18×27.56×25.59 | I37: =SUM(130*70*65/1000000) -> 0.5915 | J37: =SUM(51.18*27.56*25.59/1728) -> 20.888442 | K37: 190 | L37: =SUM(K37*2.2) -> 418 | M37: =SUM(J11:J32) -> 11466 | N37: =SUM(M37/3.75) -> 3057.6

Sheet RA-005
A1: Saudi Search & Rescue team فريق البحث والإنقاذ السعودي | L1: LEGEND
L2: R : RESCUE | N2: RA005-A
L3: A : ALPHA | N3: RA005-A
L4: 005 : BOX NUMBER | N4: RA005-A
L5: A : ITEM NUMBER | N5: RA005-A
A6: RESCUE ALPHA
A7: BOX NUMBER RA-005
A8: S/N | B8: ITEM NUMBER | C8: MAIN ITEM DESCRIPTION | E8: SUB-ITEM | J8: PRICE (SR) | L8: REMARKS
E9: DESCRIPTION | H9: SUB-ITEM NUMBER | I9: QTY
J10: SAR | K10: USD
A11: 1 | B11: RA005-A | C11: Hydraulic Cutter & Spreader Unit جهاز قاطع – فالج ميكانيكي هيدروليكي | E11: Power Unit مضخة هورست ميكانيكية هيدروليكية | H11: RA005-A1 | I11: 1 | J11: 9200 | K11: =SUM(J11/3.75) -> 2453.3333 | L11: UN3528
E13: Hydraulic Hose ليات هيدروليك | H13: RA005-B2 | I13: 2
E15: Cutter قاطع هيدروليكي | H15: RA005-C3 | I15: 1
E17: Spreader فالج هيدروليكي | H17: RA005-D4 | I17: 1
E19: Hydraulic Oil زيت هيدروليكي | H19: RA005-E5 | I19: 2
E21: Power Unit مضخة هورست ميكانيكية هيدروليكية | H21: RA005-F6 | I21: 1
E22: Hydraulic Pump عفريته هيدروليكية | H22: RA005-F7 | I22: 2
E24: Hydraulic Pump مضخه هيدروليكية يدوية | H24: RA005-G8 | I24: 1
A29: Last up Date | B29: Taken Over By | D29: Handed Over By | F29: L×W×H | I29: Total | K29: Total Weight | M29: Total Price
A30: =TODAY() -> 46198 | B30: Mishary Al Marzouki | D30: abdulrhman Al-marhabi | F30: Cm | G30: Inch | I30: CBM | J30: CFT | K30: KG | L30: LBS | M30: SAR | N30: USD
F31: 130×70×65 | G31: 51.18×27.56×25.59 | I31: =SUM(130*70*65/1000000) -> 0.5915 | J31: =SUM(51.18*27.56*25.59/1728) -> 20.888442 | K31: 168 | L31: =SUM(K31*2.2) -> 369.6 | M31: =SUM(J11) -> 9200 | N31: =SUM(M31/3.75) -> 2453.3333

Sheet RA-006
A1: Saudi Search & Rescue team فريق البحث والإنقاذ السعودي | L1: LEGEND
L2: R : RESCUE | N2: RA006-A
L3: A : ALPHA | N3: RA006-A
L4: 006 : BOX NUMBER | N4: RA006-A
L5: A : ITEM NUMBER | N5: RA006-A
A6: RESCUE ALPHA
A7: BOX NUMBER RA-006
A8: S/N | B8: ITEM NUMBER | C8: MAIN ITEM DESCRIPTION | E8: SUB-ITEM | J8: PRICE (SR) | L8: REMARKS
E9: DESCRIPTION | H9: SUB-ITEM NUMBER | I9: QTY
J10: SAR | K10: USD
A11: 1 | B11: RA006-A | C11: landing Winch ونش إنزال | I11: 1 | J11: 9000 | K11: =SUM(J11/3.75) -> 2400
A12: 2 | B12: RA006-B | C12: Triangle landing مثلث الإنزال | I12: 1 | J12: 1100 | K12: =SUM(J12/3.75) -> 293.33333
A13: 3 | B13: RA006-C | C13: Protector edges حامي حواف قماش | I13: 4 | J13: 40 | K13: 10.666667
A14: P | B14: RA006-D | C14: Core drill (box) جهاز التقوير | E14: Core drill جهاز التقوير | H14: RA006-D1 | I14: 1 | J14: 15000 | K14: =SUM(J14/3.75) -> 4000 | L14: UN 3528
E15: Bores ريش التقوير | H15: RA006-D2 | I15: 2
E16: Connector مثبت | H16: RA006-D3 | I16: 1
E17: spark plug بوجي | H17: RA006-D4 | I17: 1
A18: 5 | B18: RA006-E | C18: Bosch drill (BIG) دريل بوش كبير | E18: Bosch drill (BIG) دريل بوش كبير | H18: RA006-E1 | I18: 1 | J18: 820 | K18: 218.66667
E19: Hancle حامل | H19: RA006-E2 | I19: 1
E20: DRILL BOLTS 55 MM براغي حفر 55 مم | H20: RA006-E3 | I20: 1
E21: Drill bolts مسمار حفر | H21: RA006-E4 | I21: 4
E22: راس تكسير chisel flat drill | H22: RA006-E5 | I22: 4
A23: 6 | B23: RA006-F | C23: Anchore bolt فشر | I23: 8 | J23: 20 | K23: =SUM(J23/3.75) -> 5.3333333
A24: 7 | B24: RA006-G | C24: Iron Carbbiners كربينة حديد | I24: 6 | J24: 68 | K24: =SUM(J24/3.75) -> 18.133333
A25: 8 | B25: RA006-H | C25: شطرطون TAPE | I25: 4 | J25: 15 | K25: 4
A26: 9 | B26: RA006-I | C26: Landing equipment bag شنطة معدات الإنزال | E26: Tightening belt حزام تأمين ( برأسين) | H26: RA006-I1 | I26: 2 | J26: 4000 | K26: 1066.6667
E27: سبت تثبيت مفردة anchor straps | H27: RA006-I2 | I27: 1
E28: جهاز لشد الحبال ازرق Rope Fit Device | H28: RA006-I3 | I28: 2
E29: ROPE حبل | H29: RA006-I4 | I29: 2
E30: carabiners كربينات المنيوم | H30: RA006-I5 | I30: 5
E31: safety harness حزام تأمين منقذ | H31: RA006-I6 | I31: 2
E32: chair for Injured كرسي مصاب | H32: RA006-I7 | I32: 1
E33: بكرة مفردة وسط single medium pulley | H33: RA006-I8 | I33: 1
E34: حامي حبال rope wrapper | H34: RA006-I9 | I34: 2
E35: هرنس herness | H35: RA006-I10 | I35: 1
E36: أي دي ID | H36: RA006-I11 | I36: 1
E37: مونكي MONKI | H37: RA006-I12 | I37: 1
A39: Last up Date | B39: Taken Over By | D39: Handed Over By | F39: L×W×H | I39: Total | K39: Total Weight | M39: Total Price
B40: Abdulrahman Al-Shakrah | D40: abdulrhman Al-marhabi | F40: Cm | G40: Inch | I40: CBM | J40: CFT | K40: KG | L40: LBS | M40: SAR | N40: USD
F41: 130×70×65 | G41: 51.18×27.56×25.59 | I41: =SUM(130*70*65/1000000) -> 0.5915 | J41: =SUM(51.18*27.56*25.59/1728) -> 20.888442 | K41: 135 | L41: =SUM(K41*2.2) -> 297 | M41: =SUM(J11:J37) -> 30063 | N41: =SUM(M41/3.75) -> 8016.8

Sheet عربةRA-007
A1: Saudi Search & Rescue team فريق البحث والإنقاذ السعودي | L1: LEGEND
L2: R : RESCUE | N2: RA007-A
L3: A : ALPHA | N3: RA007-A
L4: 007 : TROLLEY NUMBER | N4: RA007-A
L5: A : ITEM NUMBER | N5: RA007-A
A6: RESCUE ALPHA
A7: TROLLEY NUMBER RA-007
A8: S/N | B8: ITEM NUMBER | C8: MAIN ITEM DESCRIPTION | E8: SUB-ITEM | J8: PRICE (SR) | L8: REMARKS
E9: DESCRIPTION | H9: SUB-ITEM NUMBER | I9: QTY
J10: SAR | K10: USD
A11: 1 | B11: RA007-A | C11: Circular Saw منشار دائري ماكيتا | I11: 1 | J11: 4530 | K11: =SUM(J11/3.75) -> 1208
A12: 2 | B12: RA007-B | C12: Drop Saw منشار قطع الخشب دائري | I12: 1 | J12: 785 | K12: =SUM(J12/3.75) -> 209.33333
A13: 3 | B13: RA007-C | C13: Nail Gun battery مسدس مسامير بطارية | E13: freighter شاحن | H13: RA007-C1 | I13: 2 | J13: 1200 | K13: =SUM(J13/3.75) -> 320
E14: Nail Gun battery مسدس مسامير بطارية | H14: RA007-C2 | I14: 2
E15: battery بطارية | H15: RA007-C3 | I15: 2
A16: 4 | B16: RA007-D | C16: Hammer مطرقه | I16: 5 | J16: 80 | K16: =SUM(J16/3.75) -> 21.333333
A17: 5 | B17: RA007-E | C17: Nail Box صندوق مسامير | E17: nail مسامير | H17: RA007-E1 | I17: 45 | J17: 460 | K17: =SUM(J17/3.75) -> 122.66667
E18: Measuring tape متر قياس | H18: RA007-E2 | I18: 3
E19: Pencils اقلام رصاص | H19: RA007-E3 | I19: 9
E20: L-square مربع رسم | H20: RA007-E4 | I20: 3
E21: Spirit level ميزان مائي | H21: RA007-E5 | I21: 2
A22: 6 | B22: RA007-F | C22: Rulers مساطر | I22: 1 | J22: 20 | K22: =SUM(J22/3.75) -> 5.3333333
A23: 7 | B23: RA007-G | C23: Nail Removel اداة نزع المسامير | I23: 2 | J23: 30 | K23: =SUM(J23/3.75) -> 8
A24: 8 | B24: RA007-H | C24: Install tool اداة تثبيت | I24: 2 | J24: 18 | K24: =SUM(J24/3.75) -> 4.8
A25: 9 | B25: RA007-I | C25: Stakes أوتاد | I25: 16 | J25: 50 | K25: =SUM(J25/3.75) -> 13.333333
A26: 10 | B26: RA007-J | C26: حزام نجارة Carpenter's Tool Belt | I26: 5 | J26: 400 | K26: =SUM(J26/3.75) -> 106.66667
A27: 11 | B27: RA007-K | C27: Saw Spare قرص احتياطي | I27: 2 | J27: 450 | K27: =SUM(J27/3.75) -> 120
A28: 12 | B28: RA007-L | C28: Normal Hand saw منشار يدوي عادي | I28: 3 | J28: 30 | K28: =SUM(J28/3.75) -> 8
A29: 13 | B29: RA007-M | C29: Makita Cordless recipro Saw ماكيتا منشار ترددي | E29: Charging base قاعدة شاحن لبطاريتين ( مدخلين ) | H29: RA007-M1 | I29: 1 | J29: 6665 | K29: =SUM(J29/3.75) -> 1777.3333
E30: Bits ريش | H30: RA007-M2 | I30: 2
E31: Bettry بطارية | H31: RA007-M3 | I31: 2
A32: 14 | B32: RA007-N | C32: Flower Bolt وردة مسمار | I32: 20 | J32: 30 | K32: =SUM(J32/3.75) -> 8
A33: 15 | B33: RA007-O | C33: Carpentry anchor خابور نجارة | I33: 20 | J33: 30 | K33: =SUM(J33/3.75) -> 8
A34: 16 | B34: RA007-P | C34: Bosch hammer drill جهاز حفر وتكسير بوش كهربائي | E34: Bosch hammer drill جهاز حفر وتكسير بوش كهربائي | H34: RA007-P1 | I34: 1 | J34: 3500 | K34: =SUM(J34/3.75) -> 933.33333
E35: Drill bits ريش حفر وتكسير | H35: RA007-P2 | I35: 3
E36: Wood Drill bits ريش حفر خشب مقاس 14 | H36: RA007-P3 | I36: 1
A37: 17 | B37: RA007-Q | C37: 15 cm Wood Nail مسمار خشب 15سم | I37: 20 | J37: 30 | K37: =SUM(J37/3.75) -> 8
A38: 18 | B38: RA007-R | C38: 8 cm Wood NailBOX مسماركرتون 8سم | I38: 1 | J38: 30 | K38: =SUM(J38/3.75) -> 8
A39: 19 | B39: RB007-S | C39: عدة مبرد جنزير خشب WOOD TRACK FILE KIT | I39: 1 | J39: 50 | K39: =SUM(J39/3.75) -> 13.333333
A43: Last up Date | B43: Taken Over By | D43: Handed Over By | F43: L×W×H | I43: Total | K43: Total Weight | M43: Total Price
...

Sheet RA-008
A1: Saudi Search & Rescue team فريق البحث والإنقاذ السعودي | L1: LEGEND
L2: R : RESCUE | N2: RA008-A
L3: A : ALPHA | N3: RA008-A
L4: 008 : BOX NUMBER | N4: RA008-A
L5: A : ITEM NUMBER | N5: RA008-A
A6: RESCUE ALPHA
A7: BOX NUMBER RA-008
A8: S/N | B8: ITEM NUMBER | C8: MAIN ITEM DESCRIPTION | E8: SUB-ITEM | J8: PRICE (SR) | L8: REMARKS
E9: DESCRIPTION | H9: SUB-ITEM NUMBER | I9: QTY
J10: SAR | K10: USD
A11: 1 | B11: RA008-A | C11: UltRB Pulley بكرة مفردة كبيرة | I11: 1 | J11: 520 | K11: =SUM(J11/3.75) -> 138.66667
A13: 2 | B13: RA008-B | C13: Double pulley بكرة مزدوجه | I13: 4 | J13: 870 | K13: =SUM(J13/3.75) -> 232
A15: 3 | B15: RA008-C | C15: Single pulley بكره مفرده وسط | I15: 4 | J15: 1000 | K15: =SUM(J15/3.75) -> 266.66667
A17: 4 | B17: RA008-D | C17: Single pulley small بكره مفرده صغيره | I17: 3 | J17: 540 | K17: =SUM(J17/3.75) -> 144
A19: 5 | B19: RA008-E | C19: Tandem pulley بكرة مزدوجة متباعدة | I19: 2 | J19: 1040 | K19: =SUM(J19/3.75) -> 277.33333
A21: 6 | B21: RA008-F | C21: Anchor plate big حلقة تجميع كبيرة | I21: 2 | J21: 260 | K21: =SUM(J21/3.75) -> 69.333333
A23: 7 | B23: RA008-G | C23: Anchor plate small حلقة تجميع صغيرة | I23: 2 | J23: 175 | K23: =SUM(J23/3.75) -> 46.666667
A25: 8 | B25: RA008-H | C25: Rope Fit Device (Blue) جهاز لشد الحبال أزرق | I25: 2 | J25: 85 | K25: =SUM(J25/3.75) -> 22.666667
A27: 9 | B27: RA008-I | C27: Rope Fit Device (Gold) جهاز لشد الحبال ذهبي | I27: 4 | J27: 85 | K27: =SUM(J27/3.75) -> 22.666667
A29: 10 | B29: RA008-J | C29: Climbing Device Right Hand (Monkey) جهاز صعود وشد يمين (مونكي) | I29: 6 | J29: 500 | K29: =SUM(J29/3.75) -> 133.33333
A31: 11 | B31: RA008-K | C31: Climbing Device left Hand (Monkey) جهاز صعود وشد يسار (مونكي) | I31: 2 | J31: 200 | K31: =SUM(J31/3.75) -> 53.333333
A33: 12 | B33: RA008-L | C33: Petzl ID Device جهاز إنزال يدوي ( الاي دي) | I33: 6 | J33: 8070 | K33: =SUM(J33/3.75) -> 2152
... A67: 29 | B67: RA008-Ac | C67: ground sheet شراع ارضي | I67: 1 | J67: 20 | K67: =SUM(J67/3.75) -> 5.3333333
A76: Last up Date | B76: Taken Over By | D76: Handed Over By | F76: L×W×H | I76: Total | K76: Total Weight | M76: Total Price
A77: =TODAY() -> 46198 | B77: Mishary Al Marzouki | D77: abdulrhman Al-marhabi | F77: Cm | G77: Inch | I77: CBM | J77: CFT | K77: KG | L77: LBS | M77: SAR | N77: USD
F78: 130×70×65 | G78: 51.18×27.56×25.59 | I78: =SUM(130*70*65/1000000) -> 0.5915 | J78: =SUM(51.18*27.56*25.59/1728) -> 20.888442 | K78: 125 | L78: =SUM(K78*2.2) -> 275 | M78: =SUM(J11:J66) -> 32354 | N78: =SUM(M78/3.75) -> 8627.7333

Sheet عربة 9
A17: Saudi Search & Rescue team فريق البحث والإنقاذ السعودي | L17: LEGEND
L18: R : RESCUE | N18: RA009-A
L19: A : ALPHA | N19: RA009-A
L20: 009 :TROLLEY NUMBER | N20: RA009-A
L21: A : ITEM NUMBER | N21: RA009-A
A22: RESCUE ALPHA
A23: TROLLEY NUMBER RA-009
A24: S/N | B24: ITEM NUMBER | C24: MAIN ITEM DESCRIPTION | E24: SUB-ITEM | J24: PRICE (SR) | L24: REMARKS
E25: DESCRIPTION | H25: SUB-ITEM NUMBER | I25: QTY
J26: SAR | K26: USD
A27: 1 | B27: RA009-A | C27: طفاية حريق ماء Water Fire Extinguisher | I27: 1 | J27: 500 | K27: =SUM(J27/3.75) -> 133.33333 | L27: UN 1044
A28: 2 | B28: RA009-B | C28: Fire BLAKET بطانية حريق | I28: 1 | J28: 500 | K28: 133
A29: 3 | B29: RA009-C | C29: spare parts قطع غيار لحام | I29: 2 | J29: 200 | K29: =SUM(J29/3.75) -> 53.333333
A30: 4 | B30: RA009-D | C30: Gloves قفازات | I30: 2 | J30: 120 | K30: =SUM(J30/3.75) -> 32
A31: 5 | B31: RA009-E | C31: منظم ضغط اكسجين Oxygen pressure regulator | I31: 1 | J31: 200 | K31: 53.333333
A32: 6 | B32: RA009-F | C32: welding clothing لبس لحام | I32: 2 | J32: 800 | K32: 133.33333
A33: 7 | B33: RA009-G | C33: Cutting System اكسسوارات جهاز اللحام | E33: welding helmet خوذة لحام | H33: RA009-G1 | I33: 2 | J33: 2462 | K33: =SUM(J33/3.75) -> 656.53333
E34: Cutting torch مسدس قطع | H34: RA009-G2 | I34: 2
E35: Flint ولاعة | H35: RA009-G3 | I35: 2
E37: welding hoses ليات لحام | H37: RA009-G4 | I37: 2
A38: 8 | B38: RA009-H | C38: BOOTS جزمة | I38: 1 | J38: 150 | K38: 40
A39: 9 | B39: RA009-I | C39: Liquid Fuel Pressure Cylinder اسطوانة ضغط وقود سائل | I39: 1 | J39: 3807.49 | K39: =SUM(J39/3.75) -> 1015.3307 | L39: UN 3528
A40: 10 | B40: RA009-J | C40: SCREWDRIVER مفك | I40: 1 | J40: 15 | K40: 4
A42: Last up Date | B42: Taken Over By | D42: Handed Over By | F42: L×W×H | I42: Total | K42: Total Weight | M42: Total Price
A43: =TODAY() -> 46198 | B43: Mishary Al Marzouki | D43: abdulrhman Al-marhabi | F43: Cm | G43: Inch | I43: CBM | J43: CFT | K43: KG | L43: LBS | M43: SAR | N43: USD
F44: 130×70×65 | G44: 51.18×27.56×25.59 | I44: =SUM(130*70*65/1000000) -> 0.5915 | J44: =SUM(51.18*27.56*25.59/1728) -> 20.888442 | K44: 154 | L44: =SUM(K44*2.2) -> 338.8 | M44: =SUM(J27:J40) -> 8754.49 | N44: =SUM(M44/3.75) -> 2334.5307

Sheet SA-001
A1: Saudi Search & Rescue team فريق البحث والإنقاذ السعودي | L1: LEGEND
L2: R : RESCUE | N2: RA-SA001-A
L3: A : ALPHA | N3: RA-SA001-A
L4: 001 : BOX NUMBER | N4: RA-SA001-A
L5: A : ITEM NUMBER | N5: RA-SA001-A
A6: RESCUE ALPHA
A7: BOX NUMBER RA-SA-001
A8: S/N | B8: ITEM NUMBER | C8: MAIN ITEM DESCRIPTION | E8: SUB-ITEM | J8: PRICE (SR) | L8: REMARKS
E9: DESCRIPTION | H9: SUB-ITEM NUMBER | I9: QTY
J10: SAR | K10: USD
A11: 1 | B11: RA-SA-001A | C11: Oxygen Cyclinder اسطوانة اكسجين | I11: 1 | J11: 1520 | K11: =SUM(J11/3.75) -> 405.33333 | L11: UN1002
A13: 2 | B13: RA-SA-001B | C13: Cylinder Holder حاملة اسطوانة | I13: 1
A15: 3 | B15: RA-SA-001C | C15: Face Mask قناع للوجه | I15: 1
A32: Last up Date | B32: Taken Over By | D32: Handed Over By | F32: L×W×H | I32: Total | K32: Total Weight | M32: Total Price
A33: =TODAY() -> 46198 | B33: Mishary Al Marzouki | D33: abdulrhman Al-marhabi | F33: Cm | G33: Inch | I33: CBM | J33: CFT | K33: KG | L33: LBS | M33: SAR | N33: USD
F34: 79×32×49 | G34: 31.1×12.6×19.29 | I34: =SUM(79*32*49/1000000) -> 0.123872 | J34: =SUM(31.1*12.6*19.29/1728) -> 4.3744094 | K34: 16 | L34: =SUM(K34*2.2) -> 35.2 | M34: =SUM(J11) -> 1520 | N34: =SUM(M34/3.75) -> 405.33333

Sheet SA-002
A1: Saudi Search & Rescue team فريق البحث والإنقاذ السعودي | L1: LEGEND
L2: R : RESCUE | N2: RA-SA002-A
L3: A : ALPHA | N3: RA-SA002-A
L4: 002 : BOX NUMBER | N4: RA-SA002-A
L5: A : ITEM NUMBER | N5: RA-SA002-A
A6: RESCUE ALPHA
A7: BOX NUMBER RA-SA-002
A8: S/N | B8: ITEM NUMBER | C8: MAIN ITEM DESCRIPTION | E8: SUB-ITEM | J8: PRICE (SR) | L8: REMARKS
E9: DESCRIPTION | H9: SUB-ITEM NUMBER | I9: QTY
J10: SAR | K10: USD
A11: 1 | B11: RA-SA-002A | C11: Oxygen Cyclinder اسطوانة اكسجين | I11: 1 | J11: 1520 | K11: =SUM(J11/3.75) -> 405.33333 | L11: UN1002
A13: 2 | B13: RA-SA-002B | C13: Cylinder Holder حاملة اسطوانة | I13: 1
A15: 3 | B15: RA-SA-002C | C15: Face Mask قناع للوجه | I15: 1
A32: Last up Date | B32: Taken Over By | D32: Handed Over By | F32: L×W×H | I32: Total | K32: Total Weight | M32: Total Price
A33: =TODAY() -> 46198 | B33: Mishary Al Marzouki | D33: abdulrhman Al-marhabi | F33: Cm | G33: Inch | I33: CBM | J33: CFT | K33: KG | L33: LBS | M33: SAR | N33: USD
F34: 79×32×49 | G34: 31.1×12.6×19.29 | I34: =SUM(79*32*49/1000000) -> 0.123872 | J34: =SUM(31.1*12.6*19.29/1728) -> 4.3744094 | K34: 18 | L34: =SUM(K34*2.2) -> 39.6 | M34: =SUM(J11) -> 1520 | N34: =SUM(M34/3.75) -> 405.33333

Sheet SA-003
A1: Saudi Search & Rescue team فريق البحث والإنقاذ السعودي | L1: LEGEND
L2: R : RESCUE | N2: RA-SA003-A
L3: A : ALPHA | N3: RA-SA003-A
L4: 003 : BOX NUMBER | N4: RA-SA003-A
L5: A : ITEM NUMBER | N5: RA-SA003-A
A6: RESCUE ALPHA
A7: BOX NUMBER RA-SA-003
A8: S/N | B8: ITEM NUMBER | C8: MAIN ITEM DESCRIPTION | E8: SUB-ITEM | J8: PRICE (SR) | L8: REMARKS
E9: DESCRIPTION | H9: SUB-ITEM NUMBER | I9: QTY
J10: SAR | K10: USD
A11: 1 | B11: RA-SA-003A | C11: Oxygen Cyclinder اسطوانة اكسجين | I11: 1 | J11: 1520 | K11: =SUM(J11/3.75) -> 405.33333 | L11: UN 1002
A13: 2 | B13: RA-SA-003B | C13: Cylinder Holder حاملة اسطوانة | I13: 1
A15: 3 | B15: RA-SA-003C | C15: Face Mask قناع للوجه | I15: 1
A32: Last up Date | B32: Taken Over By | D32: Handed Over By | F32: L×W×H | I32: Total | K32: Total Weight | M32: Total Price
A33: =TODAY() -> 46198 | B33: Mishary Al Marzouki | D33: abdulrhman Al-marhabi | F33: Cm | G33: Inch | I33: CBM | J33: CFT | K33: KG | L33: LBS | M33: SAR | N33: USD
F34: 79×32×49 | G34: 31.1×12.6×19.29 | I34: =SUM(79*32*49/1000000) -> 0.123872 | J34: =SUM(31.1*12.6*19.29/1728) -> 4.3744094 | K34: 18 | L34: =SUM(K34*2.2) -> 39.6 | M34: =SUM(J11) -> 1520 | N34: =SUM(M34/3.75) -> 405.33333

Sheet SA-004
A1: Saudi Search & Rescue team فريق البحث والإنقاذ السعودي | L1: LEGEND
L2: R : RESCUE | N2: RA-SA004-A
L3: A : ALPHA | N3: RA-SA004-A
L4: 004 :BOX NUMBER | N4: RA-SA004-A
L5: A : ITEM NUMBER | N5: RA-SA004-A
A6: RESCUE ALPHA
A7: BOX NUMBER RA-SA-004
A8: S/N | B8: ITEM NUMBER | C8: MAIN ITEM DESCRIPTION | E8: SUB-ITEM | J8: PRICE (SR) | L8: REMARKS
E9: DESCRIPTION | H9: SUB-ITEM NUMBER | I9: QTY
J10: SAR | K10: USD
A11: 1 | B11: RA-SA-004A | C11: Oxygen Cyclinder اسطوانة اكسجين | I11: 1 | J11: 1520 | K11: =SUM(J11/3.75) -> 405.33333 | L11: UN 1002
A13: 2 | B13: RA-SA-004B | C13: Cylinder Holder حاملة اسطوانة | I13: 1
A15: 3 | B15: RA-SA-004C | C15: Face Mask قناع للوجه | I15: 1
A32: Last up Date | B32: Taken Over By | D32: Handed Over By | F32: L×W×H | I32: Total | K32: Total Weight | M32: Total Price
A33: =TODAY() -> 46198 | B33: Mishary Al Marzouki | D33: abdulrhman Al-marhabi | F33: Cm | G33: Inch | I33: CBM | J33: CFT | K33: KG | L33: LBS | M33: SAR | N33: USD
F34: 79×32×49 | G34: 31.1×12.6×19.29 | I34: =SUM(79*32*49/1000000) -> 0.123872 | J34: =SUM(31.1*12.6*19.29/1728) -> 4.3744094 | K34: 18 | L34: =SUM(K34*2.2) -> 39.6 | M34: =SUM(J11) -> 1520 | N34: =SUM(M34/3.75) -> 405.33333

Sheet SA-005
A1: Saudi Search & Rescue team فريق البحث والإنقاذ السعودي | L1: LEGEND
L2: R : RESCUE | N2: RA-SA005-A
L3: A : ALPHA | N3: RA-SA005-A
L4: 005 : BOX NUMBER | N4: RA-SA005-A
L5: A : ITEM NUMBER | N5: RA-SA005-A
A6: RESCUE ALPHA
A7: BOX NUMBER RA-SA-005
A8: S/N | B8: ITEM NUMBER | C8: MAIN ITEM DESCRIPTION | E8: SUB-ITEM | J8: PRICE (SR) | L8: REMARKS
E9: DESCRIPTION | H9: SUB-ITEM NUMBER | I9: QTY
J10: SAR | K10: USD
A11: 1 | B11: RA-SA-005A | C11: Multi Function SAW منشار متعدد الأغراض | E11: Multi Function SAW منشار متعدد الأغراض | H11: RA-SA-005A1 | I11: 1 | J11: 22394 | K11: 5971.7333 | L11: UN 3528
E12: مفك BugWrench | H12: RA-SA-005A2 | I12: 1
E13: Spare Saw disc قرص احتياطي | H13: RA-SA-005A3 | I13: 1
E14: AIR FILTE فلتر هواء | H14: RA-SA-005A4 | I14: 1
E15: spark plug بوجي | H15: RA-SA-005A5 | I15: 1
E16: Oil زيت | H16: RA-SA-005A6 | I16: 1
A26: Last up Date | B26: Taken Over By | D26: Handed Over By | F26: L×W×H | I26: Total | K26: Total Weight | M26: Total Price
A27: =TODAY() -> 46198 | B27: Mishary Al Marzouki | D27: abdulrhman Al-marhabi | F27: Cm | G27: Inch | I27: CBM | J27: CFT | K27: KG | L27: LBS | M27: SAR | N27: USD
F28: 86×30×46 | G28: 28.35×19.69×12.6 | I28: =SUM(72*50*32/1000000) -> 0.1152 | J28: =SUM(28.35*19.69*12.6/1728) -> 4.0702922 | K28: 28 | L28: =SUM(K28*2.2) -> 61.6 | M28: =SUM(J11) -> 22394 | N28: =SUM(M28/3.75) -> 5971.7333

Sheet SA-006
A1: Saudi Search & Rescue team فريق البحث والإنقاذ السعودي | L1: LEGEND
L2: R : RESCUE | N2: RA-SA006-A
L3: A : ALPHA | N3: RA-SA006-A
L4: 006 : BOX NUMBER | N4: RA-SA006-A
L5: A : ITEM NUMBER | N5: RA-SA006-A
A6: RESCUE ALPHA
A7: BOX NUMBER RA-SA-006
A8: S/N | B8: ITEM NUMBER | C8: MAIN ITEM DESCRIPTION | E8: SUB-ITEM | J8: PRICE (SR) | L8: REMARKS
E9: DESCRIPTION | H9: SUB-ITEM NUMBER | I9: QTY
J10: SAR | K10: USD
A11: 1 | B11: RA-SA-006A | C11: Hydraulic Multi Function SAW منشار متعدد الأغراض هيدروليكي | E11: Hydraulic Multi Function SAW منشار متعدد الأغراض هيدروليكي | H11: RA-SA-006A1 | I11: 1 | J11: 38880 | K11: 10368
E13: مفك BugWrench | H13: RA-SA-006A2 | I13: 1
E15: Spare Saw disc قرص احتياطي | H15: RA-SA-006A3 | I15: 1
A26: Last up Date | B26: Taken Over By | D26: Handed Over By | F26: L×W×H | I26: Total | K26: Total Weight | M26: Total Price
A27: =TODAY() -> 46198 | B27: Mishary Al Marzouki | D27: abdulrhman Al-marhabi | F27: Cm | G27: Inch | I27: CBM | J27: CFT | K27: KG | L27: LBS | M27: SAR | N27: USD
F28: 83×29×49 | G28: 32.68×11.42×19.29 | I28: =SUM(83*29*49/1000000) -> 0.117943 | J28: =SUM(32.68*11.42*19.29/1728) -> 4.1661667 | K28: 20 | L28: =SUM(K28*2.2) -> 44 | M28: 38880 | N28: =SUM(M28/3.75) -> 10368

Sheet SA-007
A1: Saudi Search & Rescue team فريق البحث والإنقاذ السعودي | L1: LEGEND
L2: R : RESCUE | N2: RA-SA007-A
L3: A : ALPHA | N3: RA-SA007-A
L4: 007 :BOX NUMBER | N4: RA-SA007-A
L5: A : ITEM NUMBER | N5: RA-SA007-A
A6: RESCUE ALPHA
A7: BOX NUMBER RA-SA-007
A8: S/N | B8: ITEM NUMBER | C8: MAIN ITEM DESCRIPTION | E8: SUB-ITEM | J8: PRICE (SR) | L8: REMARKS
E9: DESCRIPTION | H9: SUB-ITEM NUMBER | I9: QTY
J10: SAR | K10: USD
A11: 1 | B11: RA-SA-007A | C11: Chain Saw (Wood) منشار جنزير خشب | E11: Chain Saw (Wood) منشار جنزير خشب | H11: RA-SA-007A1 | I11: 1 | J11: 26400 | K11: 7040 | L11: UN 3528
E13: Chainsaw Guide Bar مسطرة جنزير | H13: RA-SA-007A2 | I13: 1
E15: Chain for Saw جنزير | H15: RA-SA-007A3 | I15: 2
E17: Mineral oil زيت تبريد | H17: RA-SA-007A4 | I17: 1
E19: spark plug بوجي | H19: RA-SA-007A5 | I19: 1
E21: مفك BugWrench | H21: RA-SA-007A6 | I21: 1
E23: Glasses نظارة | H23: RA-SA-007A7 | I23: 1
E25: Protection clothes لبس الوقاية من الخشب | H25: RA-SA-007A8 | I25: 1
E27: Oil زيت | H27: RA-SA-007A8 | I27: 1
A29: Last up Date | B29: Taken Over By | D29: Handed Over By | F29: L×W×H | I29: Total | K29: Total Weight | M29: Total Price
A30: =TODAY() -> 46198 | B30: Mishary Al Marzouki | D30: abdulrhman Al-marhabi | F30: Cm | G30: Inch | I30: CBM | J30: CFT | K30: KG | L30: LBS | M30: SAR | N30: USD
F31: 78×27×47 | G31: 30.71×10.63×18.5 | I31: =SUM(78*27*47/1000000) -> 0.098982 | J31: =SUM(30.71*10.63*18.5/1728) -> 3.4949508 | K31: 19 | L31: =SUM(K31*2.2) -> 41.8 | M31: =SUM(J11) -> 26400 | N31: =SUM(M31/3.75) -> 7040

Sheet SA-008
A1: Saudi Search & Rescue team فريق البحث والإنقاذ السعودي | L1: LEGEND
L2: R : RESCUE | N2: RA-SA008-A
L3: A : ALPHA | N3: RA-SA008-A
L4: 008 : BOX NUMBER | N4: RA-SA008-A
L5: A : ITEM NUMBER | N5: RA-SA008-A
A6: RESCUE ALPHA
A7: BOX NUMBER RA-SA-008
A8: S/N | B8: ITEM NUMBER | C8: MAIN ITEM DESCRIPTION | E8: SUB-ITEM | J8: PRICE (SR) | L8: REMARKS
E9: DESCRIPTION | H9: SUB-ITEM NUMBER | I9: QTY
J10: SAR | K10: USD
A11: 1 | B11: RA-SA-008A | C11: Concrete Chain Saw منشار جنزير للخرسان | E11: Concrete Chain Saw منشار جنزير للخرسان | H11: RA-SA-008A1 | I11: 1 | J11: 22600 | K11: 6026.6667 | L11: UN 3528
E13: Chainsaw Guide Bar مسطرة جنزير | H13: RA-SA-008A2 | I13: 1
E15: Chain for Saw جنزير | H15: RA-SA-008A3 | I15: 1
E17: Oil زيت | H17: RA-SA-008A4 | I17: 1
E19: مفك BugWrench | H19: RA-SA-008A5 | I19: 1
E21: spark plug بوجي | H21: RA-SA-008A6 | I21: 1
A28: Last up Date | B28: Taken Over By | D28: Handed Over By | F28: L×W×H | I28: Total | K28: Total Weight | M28: Total Price
A29: =TODAY() -> 46198 | B29: Mishary Al Marzouki | D29: abdulrhman Al-marhabi | F29: Cm | G29: Inch | I29: CBM | J29: CFT | K29: KG | L29: LBS | M29: SAR | N29: USD
F30: 88×31×42 | G30: 34.65×12.2×16.54 | I30: =SUM(88*31*42/1000000) -> 0.114576 | J30: =SUM(34.65*12.2*16.54/1728) -> 4.0462698 | K30: 12 | L30: =SUM(K30*2.2) -> 26.4 | M30: =SUM(J11) -> 22600 | N30: =SUM(M30/3.75) -> 6026.6667

Sheet SA-009
A1: Saudi Search & Rescue team فريق البحث والإنقاذ السعودي | L1: LEGEND
L2: R : RESCUE | N2: RA-SA009-A
L3: A : ALPHA | N3: RA-SA009-A
L4: 009 :BOX NUMBER | N4: RA-SA009-A
L5: A : ITEM NUMBER | N5: RA-SA009-A
A6: RESCUE ALPHA
A7: BOX NUMBER RA-SA-009
A8: S/N | B8: ITEM NUMBER | C8: MAIN ITEM DESCRIPTION | E8: SUB-ITEM | J8: PRICE (SR) | L8: REMARKS
E9: DESCRIPTION | H9: SUB-ITEM NUMBER | I9: QTY
J10: SAR | K10: USD
A11: 1 | B11: RA-SA-009A | C11: Metal Power Saw (Metal) منشار قرص حديد | E11: Metal Power Saw (Metal) منشار قرص حديد | H11: RA-SA-009A1 | I11: 1 | J11: 21570 | K11: 5752 | L11: UN 3528
E12: Matel Head Desk قرص حديد | H12: RA-SA-009A2 | I12: 4
E13: Oil زيت | H13: RA-SA-009A3 | I13: 1
E14: spark plug بوجي | H14: RA-SA-009A4 | I14: 1
E15: مفك BugWrench | H15: RA-SA-009A5 | I15: 1
E16: فلتر هواء air filter | H16: RA-SA-009A6 | I16: 1
A22: Last up Date | B22: Taken Over By | D22: Handed Over By | F22: L×W×H | I22: Total | K22: Total Weight | M22: Total Price
A23: =TODAY() -> 46198 | B23: Mishary Al Marzouki | D23: abdulrhman Al-marhabi | F23: Cm | G23: Inch | I23: CBM | J23: CFT | K23: KG | L23: LBS | M23: SAR | N23: USD
F24: 72×50×32 | G24: 28.35×19.69×12.6 | I24: =SUM(72*50*32/1000000) -> 0.1152 | J24: =SUM(28.35*19.69*12.6/1728) -> 4.0702922 | K24: 26 | L24: =SUM(K24*2.2) -> 57.2 | M24: =SUM(J11) -> 21570 | N24: =SUM(M24/3.75) -> 5752

Sheet SA-0010
A1: Saudi Search & Rescue team فريق البحث والإنقاذ السعودي | L1: LEGEND
L2: R : RESCUE | N2: RA-SA010-A
L3: A : ALPHA | N3: RA-SA010-A
L4: 010 : BOX NUMBER | N4: RA-SA010-A
L5: A : ITEM NUMBER | N5: RA-SA010-A
A6: RESCUE ALPHA
A7: BOX NUMBER RA-SA-010
A8: S/N | B8: ITEM NUMBER | C8: MAIN ITEM DESCRIPTION | E8: SUB-ITEM | J8: PRICE (SR) | L8: REMARKS
E9: DESCRIPTION | H9: SUB-ITEM NUMBER | I9: QTY
J10: SAR | K10: USD
A11: 1 | B11: RA-SA-010A | C11: ICS water pump مضخة ماء تعمل بالبطارية | I11: 3 | J11: 9640 | K11: =SUM(J11/3.75) -> 2570.6667
A31: Last up Date | B31: Taken Over By | D31: Handed Over By | F31: L×W×H | I31: Total | K31: Total Weight | M31: Total Price
A32: =TODAY() -> 46198 | B32: Mishary Al Marzouki | D32: abdulrhman Al-marhabi | F32: Cm | G32: Inch | I32: CBM | J32: CFT | K32: KG | L32: LBS | M32: SAR | N32: USD
F33: 40×40×104 | G33: 15.75×15.75×40.94 | I33: =SUM(40*40*104/1000000) -> 0.1664 | J33: =SUM(15.75*15.75*40.94/1728) -> 5.8771289 | K33: 43 | L33: =SUM(K33*2.2) -> 94.6 | M33: =SUM(J11) -> 9640 | N33: =SUM(M33/3.75) -> 2570.6667

Sheet SA-0011
A1: Saudi Search & Rescue team فريق البحث والإنقاذ السعودي | L1: LEGEND
L2: R : RESCUE | N2: RB-SA011-A
L3: B : BRAVO | N3: RB-SA011-A
L4: 011 : BOX NUMBER | N4: RB-SA011-A
L5: A : ITEM NUMBER | N5: RB-SA011-A
A6: RESCUE BRAVO
A7: BOX NUMBER RA-SA-011
A8: S/N | B8: ITEM NUMBER | C8: MAIN ITEM DESCRIPTION | E8: SUB-ITEM | J8: PRICE (SR) | L8: REMARKS
E9: DESCRIPTION | H9: SUB-ITEM NUMBER | I9: QTY
J10: SAR | K10: USD
A11: 1 | B11: RA-SA-011A | C11: ICS Hydraulic saw منشار هيدروليكي | I11: 1 | J11: 13000 | K11: =SUM(J11/3.75) -> 3466.6667
A13: 2 | B13: RA-SA-011A | C13: BugWrench مفك | I13: 2 | J13: 20 | K13: =SUM(J13/3.75) -> 5.3333333
A14: 3 | B14: RA-SA-011A | C14: جنزير احتياط Chain for Saw | I14: 1 | J14: 300 | K14: =SUM(J14/3.75) -> 80
A15: 4 | B15: RA-SA-011B | C15: مسطرة جنزير BERLUTI | I15: 1 | J15: 105 | K15: 28
A19: Last up Date | B19: Taken Over By | D19: Handed Over By | F19: L×W×H | I19: Total | K19: Total Weight | M19: Total Price
A20: =TODAY() -> 46198 | B20: Mishary Al Marzouki | D20: abdulrhman Al-marhabi | F20: Cm | G20: Inch | I20: CBM | J20: CFT | K20: KG | L20: LBS | M20: SAR | N20: USD
F21: 123×36×27 | G21: 48.43×14.17×10.36 | I21: =SUM(123*36*27/1000000) -> 0.119556 | J21: =SUM(48.43*14.17*10.36/1728) -> 4.1143415 | K21: 24 | L21: =SUM(K21*2.2) -> 52.8 | M21: =SUM(J11:J16) -> 13425 | N21: =SUM(M21/3.75) -> 3580

Sheet SA-0012
A1: Saudi Search & Rescue team فريق البحث والإنقاذ السعودي | L1: LEGEND
L2: R : RESCUE | N2: RA-SA012-A
L3: A : ALPHA | N3: RA-SA012-A
L4: 012 : BOX NUMBER | N4: RA-SA012-A
L5: A : ITEM NUMBER | N5: RA-SA012-A
A6: RESCUE ALPHA
A7: BOX NUMBER RA-SA-012
A8: S/N | B8: ITEM NUMBER | C8: MAIN ITEM DESCRIPTION | E8: SUB-ITEM | J8: PRICE (SR) | L8: REMARKS
E9: DESCRIPTION | H9: SUB-ITEM NUMBER | I9: QTY
J10: SAR | K10: USD
A11: 1 | B11: RA-SA-012A | C11: water pump مضخة ماء عادية | I11: 2 | J11: 100 | K11: =SUM(J11/3.75) -> 26.666667
A28: Last up Date | B28: Taken Over By | D28: Handed Over By | F28: L×W×H | I28: Total | K28: Total Weight | M28: Total Price
A29: =TODAY() -> 46198 | B29: Mishary Al Marzouki | D29: abdulrhman Al-marhabi | F29: Cm | G29: Inch | I29: CBM | J29: CFT | K29: KG | L29: LBS | M29: SAR | N29: USD
F30: 25×25×60 | G30: 9.84×9.84×23.62 | I30: 0.0375 | J30: 1.3235073 | K30: 3 | L30: 13.2 | M30: 100 | N30: 26.666667

Sheet SA-0013
A1: Saudi Search & Rescue team فريق البحث والإنقاذ السعودي | L1: LEGEND
L2: R : RESCUE | N2: RA-SA013-A
L3: A : ALPHA | N3: RA-SA013-A
L4: 013 : BOX NUMBER | N4: RA-SA013-A
L5: A : ITEM NUMBER | N5: RA-SA013-A
A6: RESCUE ALPHA
A7: BOX NUMBER RA-SA-013
A8: S/N | B8: ITEM NUMBER | C8: MAIN ITEM DESCRIPTION | E8: SUB-ITEM | J8: PRICE (SR) | L8: REMARKS
E9: DESCRIPTION | H9: SUB-ITEM NUMBER | I9: QTY
J10: SAR | K10: USD
A11: 1 | B11: RA-SA-013A | C11: pelican Light اناره | I11: 2 | J11: 11294 | K11: =SUM(J11/3.75) -> 3011.7333 | L11: UN 3481
A28: Last up Date | B28: Taken Over By | D28: Handed Over By | F28: L×W×H | I28: Total | K28: Total Weight | M28: Total Price
A29: =TODAY() -> 46198 | B29: Mishary Al Marzouki | D29: abdulrhman Al-marhabi | F29: Cm | G29: Inch | I29: CBM | J29: CFT | K29: KG | L29: LBS | M29: SAR | N29: USD
F30: 56×34×23 | G30: 22.05×13.39×9.06 | I30: =SUM(56*34*23/1000000) -> 0.043792 | J30: =SUM(22.05*13.39*9.06/1728) -> 1.5480095 | K30: 64 | L30: =SUM(K30*2.2) -> 140.8 | M30: 11294 | N30: =SUM(M30/3.75) -> 3011.7333

Sheet SA-0014
A1: Saudi Search & Rescue team فريق البحث والإنقاذ السعودي | L1: LEGEND
L2: R : RESCUE | N2: RA-SA014-A
L3: A : ALPHA | N3: RA-SA014-A
L4: 014 : BOX NUMBER | N4: RA-SA014-A
L5: A : ITEM NUMBER | N5: RA-SA014-A
A6: RESCUE ALPHA
A7: BOX NUMBER RA-SA-014
A8: S/N | B8: ITEM NUMBER | C8: MAIN ITEM DESCRIPTION | E8: SUB-ITEM | J8: PRICE (SR) | L8: REMARKS
E9: DESCRIPTION | H9: SUB-ITEM NUMBER | I9: QTY
A10: 1 | B10: RA-SA-014A | C10: LeaderLive Locator صندوق مجسات | E10: Sensors مجسات سلكية ولاسلكية | H10: RA-SA-014A1 | I10: 3\3 | J10: 149000 | K10: =SUM(J10/3.75) -> 39733.333 | L10: UN 3481
E11: Sensor connecting cables كيبل للمجسات | H11: RA-SA-014A2 | I11: 3
E12: headset سماعات | H12: RA-SA-014A3 | I12: 2
E13: Main unit جهاز التحكم | H13: RA-SA-014A4 | I13: 1
E14: Magnetic sensor clamp مغناطيس التثبيت | H14: RA-SA-014A5 | I14: 6
E15: INTEL SIGNAL BOOSTER انتيل مقوي اشارة | H15: RA-SA-014A6 | I15: 1
E16: charging batteries بطاريات شحن | H16: RA-SA-014A7 | I16: 2
E17: Batteries بطاريات جافة | H17: RA-SA-014A8 | I17: 1
E18: Mic AND LINK CABLE كيبل وصلة مع مايك | H18: RA-SA-014A10 | I18: 1
E19: حماية حزام belt protection | H19: RA-SA-014A11 | I19: 1
E20: batteries charging شاحن بطاريات | H20: RB-SA-014A12 | I20: 1
A21: Last up Date | B21: Taken Over By | D21: Handed Over By | F21: L×W×H | I21: Total | K21: Total Weight | M21: Total Price
A22: =TODAY() -> 46198 | B22: Mishary Al Marzouki | D22: abdulrhman Al-marhabi | F22: Cm | G22: Inch | I22: CBM | J22: CFT | K22: KG | L22: LBS | M22: SAR | N22: USD
F23: 65×51×23 | G23: 25.59×20.08×9.06 | I23: =SUM(65*51*23/1000000) -> 0.076245 | J23: =SUM(25.59*20.08*9.06/1728) -> 2.6941294 | K23: 20 | L23: =SUM(K23*2.2) -> 44 | M23: =SUM(J10) -> 149000 | N23: =SUM(M23/3.75) -> 39733.333

Sheet SA-0015
A1: Saudi Search & Rescue team فريق البحث والإنقاذ السعودي | L1: LEGEND
L2: R : RESCUE | N2: RA-SA015-A
L3: A : ALPHA | N3: RA-SA015-A
L4: 015 : BOX NUMBER | N4: RA-SA015-A
L5: A : ITEM NUMBER | N5: RA-SA015-A
A6: RESCUE ALPHA
A7: BOX NUMBER RA-SA-015
A8: S/N | B8: ITEM NUMBER | C8: MAIN ITEM DESCRIPTION | E8: SUB-ITEM | J8: PRICE (SR) | L8: REMARKS
E9: DESCRIPTION | H9: SUB-ITEM NUMBER | I9: QTY
J10: SAR | K10: USD
A11: 1 | B11: RA-SA-015A | C11: Search Camera كاميرا بحث | E11: Camera كاميرا | H11: RA-SA-015A1 | I11: 1 | J11: 12000 | K11: =SUM(J11/3.75) -> 3200
E12: Control screen شاشة تحكم | H12: RA-SA-015A2 | I12: 1
E13: Installed مثبت | H13: RA-SA-015A3 | I13: 1
E14: Belt حزام | H14: RA-SA-015A4 | I14: 2
E15: SD card بطاقة ذاكرة | G15: Plugs سدادات | H15: RA-SA-015A5 | I15: 1 Card
E16: plug فيش | H16: RA-SA-015A6 | I16: 2
E17: protection cover غطاء حماية | H17: RA-SA-015A7 | I17: 1
E18: A Stick عصا موصلة بأسلاك | H18: RA-SA-015A8 | I18: 1
E19: Headphone سماعة | H19: RA-SA-015A9 | I19: 2
E20: SHARGER شاحن | H20: RA-SA-015A10 | I20: 1
E21: battery بطاريات | H21: RA-SA-015A11 | I21: 2
A22: Last up Date | B22: Taken Over By | D22: Handed Over By | F22: L×W×H | I22: Total | K22: Total Weight | M22: Total Price
A23: =TODAY() -> 46198 | B23: Mishary Al Marzouki | D23: abdulrhman Al-marhabi | F23: Cm | G23: Inch | I23: CBM | J23: CFT | K23: KG | L23: LBS | M23: SAR | N23: USD
F24: 121×39×16 | G24: 47.64×15.35×6.3 | I24: =SUM(121*39*16/1000000) -> 0.075504 | J24: =SUM(47.64*15.35*6.3/1728) -> 2.6661031 | K24: 16 | L24: =SUM(K24*2.2) -> 35.2 | M24: =SUM(J11) -> 12000 | N24: =SUM(M24/3.75) -> 3200

Sheet SA-0016
A1: Saudi Search & Rescue team فريق البحث والإنقاذ السعودي | L1: LEGEND
L2: R : RESCUE | N2: RA-SA016-A
L3: A : ALPHA | N3: RA-SA016-A
L4: 016 : BOX NUMBER | N4: RA-SA016-A
L5: A : ITEM NUMBER | N5: RA-SA016-A
A6: RESCUE ALPHA
A7: BOX NUMBER RA-SA-016
A8: S/N | B8: ITEM NUMBER | C8: MAIN ITEM DESCRIPTION | E8: SUB-ITEM | J8: PRICE (SR) | L8: REMARKS
E9: DESCRIPTION | H9: SUB-ITEM NUMBER | I9: QTY
J10: SAR | K10: USD
A11: 1 | B11: RA-SA-016A | C11: Electric Concrete Breaker كمبروشر خرسانة | E11: Electric Concrete Breaker كمبروشر خرسانة | I11: 1 | J11: 3750 | K11: =SUM(J11/3.75) -> 1000
E13: concrete Breaker Heads رأس تكسير | I13: 2
A32: Last up Date | B32: Taken Over By | D32: Handed Over By | F32: L×W×H | I32: Total | K32: Total Weight | M32: Total Price
A33: =TODAY() -> 46198 | B33: Mishary Al Marzouki | D33: abdulrhman Al-marhabi | F33: Cm | G33: Inch | I33: CBM | J33: CFT | K33: KG | L33: LBS | M33: SAR | N33: USD
F34: 89×35×23 | G34: 35.04×13.78×9.06 | I34: =SUM(89*35*23/1000000) -> 0.071645 | J34: =SUM(35.04*13.78*9.06/1728) -> 2.5316157 | K34: 25 | L34: 41.8 | M34: =SUM(J11) -> 3750 | N34: =SUM(M34/3.75) -> 1000

Sheet SA-0018
A1: Saudi Search & Rescue team فريق البحث والإنقاذ السعودي | L1: LEGEND
L2: R : RESCUE | N2: RA-SA018-A
L3: A : ALPHA | N3: RA-SA018-A
L4: 018 : BOX NUMBER | N4: RA-SA018-A
L5: A : ITEM NUMBER | N5: RA-SA018-A
A6: RESCUE ALPHA
A7: BOX NUMBER RA-SA-018
A8: S/N | B8: ITEM NUMBER | C8: MAIN ITEM DESCRIPTION | E8: SUB-ITEM | J8: PRICE (SR) | L8: REMARKS
E9: DESCRIPTION | H9: SUB-ITEM NUMBER | I9: QTY
J10: SAR | K10: USD
A11: 1 | B11: RA-SA-018A | C11: Battery OpeRBted Combi Tool (Cutter & Spreader) (Box) جهاز قص –وفالج يعمل على البطارية | E11: Combi Tool Cutter &Spreader جهاز قص | H11: RA-SA-018A1 | I11: 1 | J11: 4589 | K11: =SUM(J11/3.75) -> 1223.7333
E13: Head spare رأس احتياط | H13: RA-SA-018A2 | I13: 1
E15: charging batteries بطاريات شحن | H15: RA-SA-018A3 | I15: 2
E17: Belt حزام | H17: RA-SA-018A4 | I17: 1
A34: Last up Date | B34: Taken Over By | D34: Handed Over By | F34: L×W×H | I34: Total | K34: Total Weight | M34: Total Price
A35: =TODAY() -> 46198 | B35: Mishary Al Marzouki | D35: abdulrhman Al-marhabi | F35: Cm | G35: Inch | I35: CBM | J35: CFT | K35: KG | L35: LBS | M35: SAR | N35: USD
F36: 88×53×33 | G36: 34.65×20.87×12.99 | I36: =SUM(88*53*33/1000000) -> 0.153912 | J36: =SUM(34.65*20.87*12.99/1728) -> 5.4361459 | K36: 30 | L36: =SUM(K36*2.2) -> 66 | M36: =SUM(J11) -> 4589 | N36: =SUM(M36/3.75) -> 1223.7333

Sheet SA-0019
A1: Saudi Search & Rescue team فريق البحث والإنقاذ السعودي | L1: LEGEND
L2: R : RESCUE | N2: RA-SA019-A
L3: A : ALPHA | N3: RA-SA019-A
L4: 019 : BOX NUMBER | N4: RA-SA019-A
L5: A : ITEM NUMBER | N5: RA-SA019-A
A6: RESCUE ALPHA
A7: BOX NUMBER RA-SA-019
A8: S/N | B8: ITEM NUMBER | C8: MAIN ITEM DESCRIPTION | E8: SUB-ITEM | J8: PRICE (SR) | L8: REMARKS
E9: DESCRIPTION | H9: SUB-ITEM NUMBER | I9: QTY
J10: SAR | K10: USD
A11: 1 | B11: RA-SA-019A | C11: Clean Cut triangle مثلث الرفع للقطع النظيف | I11: 1 | J11: 7200 | K11: =SUM(J11/3.75) -> 1920
A32: Last up Date | B32: Taken Over By | D32: Handed Over By | F32: L×W×H | I32: Total | K32: Total Weight | M32: Total Price
A33: =TODAY() -> 46198 | B33: Mishary Al Marzouki | D33: abdulrhman Al-marhabi | F33: Cm | G33: Inch | I33: CBM | J33: CFT | K33: KG | L33: LBS | M33: SAR | N33: USD
F34: 263×23×20 | G34: 103.54×9.06×7.87 | I34: =SUM(263*23*20/1000000) -> 0.12098 | J34: =SUM(103.54*9.06*7.87/1728) -> 4.2723552 | K34: 20 | L34: =SUM(K34*2.2) -> 44 | M34: =SUM(J11) -> 7200 | N34: =SUM(M34/3.75) -> 1920

Sheet SA-020
A1: Saudi Search & Rescue team فريق البحث والإنقاذ السعودي | L1: LEGEND
L2: R : RESCUE | N2: RA-SA020-A
L3: A : ALPHA | N3: RA-SA020-A
L4: 020 : BOX NUMBER | N4: RA-SA020-A
L5: A : ITEM NUMBER | N5: RA-SA020-A
A6: RESCUE ALPHA
A7: BOX NUMBER RA-SA-020
A8: S/N | B8: ITEM NUMBER | C8: MAIN ITEM DESCRIPTION | E8: SUB-ITEM | J8: PRICE (SR) | L8: REMARKS
E9: DESCRIPTION | H9: SUB-ITEM NUMBER | I9: QTY
J10: SAR | K10: USD
A11: 1 | B11: RA-SA-020A | C11: ICS Hydraulic pump ماطور هيدروليكي | I11: 1 | J11: 50000 | K11: =SUM(J11/3.75) -> 13333.333 | L11: UN 3528
A32: Last up Date | B32: Taken Over By | D32: Handed Over By | F32: L×W×H | I32: Total | K32: Total Weight | M32: Total Price
A33: =TODAY() -> 46198 | B33: Mishary Al Marzouki | D33: abdulrhman Al-marhabi | F33: Cm | G33: Inch | I33: CBM | J33: CFT | K33: KG | L33: LBS | M33: SAR | N33: USD
F34: 63×60×76 | G34: 24.8×23.62×29.92 | I34: =SUM(63*60*76/1000000) -> 0.28728 | J34: =SUM(24.8*23.62*29.92/1728) -> 10.142603 | K34: 174 | L34: =SUM(K34*2.2) -> 382.8 | M34: =SUM(J11) -> 50000 | N34: =SUM(M34/3.75) -> 13333.333

Sheet SA-021
A1: Saudi Search & Rescue team فريق البحث والإنقاذ السعودي | L1: LEGEND
L2: R : RESCUE | N2: RA-SA021-A
L3: A : ALPHA | N3: RA-SA021-A
L4: 021 : BOX NUMBER | N4: RA-SA021-A
L5: A : ITEM NUMBER | N5: RA-SA021-A
A6: RESCUE ALPHA
A7: BOX NUMBER RA-SA-021
A8: S/N | B8: ITEM NUMBER | C8: MAIN ITEM DESCRIPTION | E8: SUB-ITEM | J8: PRICE (SR) | L8: REMARKS
E9: DESCRIPTION | H9: SUB-ITEM NUMBER | I9: QTY
J10: SAR | K10: USD
A11: 1 | B11: RA-SA-021A | C11: Junkin stretcher نقالة صفراء | I11: 1 | J11: 5293 | K11: =SUM(J11/3.75) -> 1411.4667
A12: 2 | B12: RA-SA-021B | C12: Splint fixation back جبيرة تثبيت الظهر | I12: 1 | J12: 532 | K12: 142
A13: 3 | B13: RA-SA-021C | C13: Spine Board Stretcher نقالة لوحية برتقالية | I13: 1 | J13: 725 | K13: 193
A14: 4 | B14: RA-SA-021D | C14: Splint head جبيرة تثبيت الرأس | I14: 1 | J14: 322 | K14: 86
A15: 5 | B15: RA-SA-021E | C15: Aspiring Stretcher Bridle ربطة نقالة رباعية | I15: 1 | J15: 265 | K15: 71
A16: 6 | B16: RA-SA-021F | C16: Stretcher chair نقالة كرسي | I16: 1 | J16: 798 | K16: 213
A17: 7 | B17: RA-SA-021G | C17: id Camp آي دي | I17: 1 | J17: 1121 | K17: =SUM(J17/3.75) -> 298.93333
A18: 8 | B18: RA-SA-021H | C18: Folding stretcher نقالة رول | I18: 1 | J18: 698 | K18: 186
A19: 9 | B19: RA-SA-021I | C19: Splint Parties جبيرة اطراف | I19: 1 | J19: 322 | K19: 86
A24: Last up Date | B24: Taken Over By | D24: Handed Over By | F24: L×W×H | I24: Total | K24: Total Weight | M24: Total Price
A25: =TODAY() -> 46198 | B25: Mishary Al Marzouki | D25: abdulrhman Al-marhabi | F25: Cm | G25: Inch | I25: CBM | J25: CFT | K25: KG | L25: LBS | M25: SAR | N25: USD
F26: 220×70×40 | G26: 86.61×27.56×19.29 | I26: 0.616 | J26: 26.646228 | K26: 55 | L26: 149.6 | M26: =SUM(J11:J19) -> 10076 | N26: =SUM(M26/3.75) -> 2686.9333

Sheet SA-022
A1: Saudi Search & Rescue team فريق البحث والإنقاذ السعودي | L1: LEGEND
L2: R : RESCUE | N2: RA-SA022-A
L3: A : ALPHA | N3: RA-SA022-A
L4: 022 : BOX NUMBER | N4: RA-SA022-A
L5: A : ITEM NUMBER | N5: RA-SA022-A
A6: RESCUE ALPHA
A7: BOX NUMBER RA-SA-022
A8: S/N | B8: ITEM NUMBER | C8: MAIN ITEM DESCRIPTION | E8: SUB-ITEM | J8: PRICE (SR) | L8: REMARKS
E9: DESCRIPTION | H9: SUB-ITEM NUMBER | I9: QTY
J10: SAR | K10: USD
A11: 1 | B11: RA-SA-022A | C11: Color spray بخاخ بويه | I11: 3 | J11: 15 | K11: =SUM(J11/3.75) -> 4 | L11: UN 1950
A13: 2 | B13: RA-SA-022B | C13: Cordion كرديون | I13: 1 | J13: 60 | K13: =SUM(J13/3.75) -> 16
A15: 3 | B15: RA-SA-022C | C15: Electric detection tool عصا كشف الكهرباء | I15: 1 | J15: 100 | K15: =SUM(J15/3.75) -> 26.666667
A17: 4 | B17: RA-SA-022D | C17: Dangerous Cordion كرديون مواد خطرة | I17: 1 | J17: 26.25 | K17: 7
A19: 6 | B19: RA-SA-022F | C19: Meters measure متر قياس | I19: 1 | J19: 50 | K19: =SUM(J19/3.75) -> 13.333333
A28: Last up Date | B28: Taken Over By | D28: Handed Over By | F28: L×W×H | I28: Total | K28: Total Weight | M28: Total Price
A29: =TODAY() -> 46198 | B29: Mishary Al Marzouki | D29: abdulrhman Al-marhabi | F29: Cm | G29: Inch | I29: CBM | J29: CFT | K29: KG | L29: LBS | M29: SAR | N29: USD
F30: 70×30×50 | G30: 27.56×11.81×19.69 | I30: =SUM(70*30*50/1000000) -> 0.105 | J30: =SUM(27.56*11.81*19.69/1728) -> 3.7087801 | K30: 9 | L30: =SUM(K30*2.2) -> 19.8 | M30: =SUM(J11:J20) -> 251.25 | N30: =SUM(M30/3.75) -> 67

Sheet SA-023
A1: Saudi Search & Rescue team فريق البحث والإنقاذ السعودي | L1: LEGEND
L2: R : RESCUE | N2: RA-SA023-A
L3: A : ALPHA | N3: RA-SA023-A
L4: 023 : BOX NUMBER | N4: RA-SA023-A
L5: A : ITEM NUMBER | N5: RA-SA023-A
A6: RESCUE ALPHA
A7: BOX NUMBER RA-SA-023
A8: S/N | B8: ITEM NUMBER | C8: MAIN ITEM DESCRIPTION | E8: SUB-ITEM | J8: PRICE (SR) | L8: REMARKS
E9: DESCRIPTION | H9: SUB-ITEM NUMBER | I9: QTY
J10: SAR | K10: USD
A11: 1 | B11: RA-SA-023A | C11: Silver Diesel Generator ماطور ديزل توليد كهرباء فضي | I11: 1 | J11: 13000 | K11: 3466.6667 | L11: UN 3528
A25: Last up Date | B25: Taken Over By | D25: Handed Over By | F25: L×W×H | I25: Total | K25: Total Weight | M25: Total Price
A26: =TODAY() -> 46198 | B26: Mishary Al Marzouki | D26: abdulrhman Al-marhabi | F26: Cm | G26: Inch | I26: CBM | J26: CFT | K26: KG | L26: LBS | M26: SAR | N26: USD
F27: 89×35×23 | G27: 35.04×13.78×9.06 | I27: =SUM(89*35*23/1000000) -> 0.071645 | J27: =SUM(35.04*13.78*9.06/1728) -> 2.5316157 | K27: 181 | L27: 41.8 | M27: =SUM(J11) -> 13000 | N27: =SUM(M27/3.75) -> 3466.6667

Sheet SA-026
A1: Saudi Search & Rescue team فريق البحث والإنقاذ السعودي | L1: LEGEND
L2: R : RESCUE | N2: RA-SA026-A
L3: A : ALPHA | N3: RA-SA026-A
L4: 026 : BOX NUMBER | N4: RA-SA026-A
L5: A : ITEM NUMBER | N5: RA-SA026-A
A6: RESCUE ALPHA
A7: BOX NUMBER RA-SA-026
A8: S/N | B8: ITEM NUMBER | C8: MAIN ITEM DESCRIPTION | E8: SUB-ITEM | J8: PRICE (SR) | L8: REMARKS
E9: DESCRIPTION | H9: SUB-ITEM NUMBER | I9: QTY
J10: SAR | K10: USD
A11: 1 | B11: RA-SA-026A | C11: Earthquake Monitor مراقب الاهتزازات | E11: Earthquake Monitor جهاز الاهتزازات الزلازل ليز | H11: RA-SA-026A1 | I11: 2 | J11: 200000 | K11: 53333.333 | L11: UN 3481
E13: Cable كيابل | H13: RA-SA-026A2 | I13: 2
E15: adopla محول 12 فولت | H15: RA-SA-026A3 | I15: 1
E17: Battery بطاريات | H17: RA-SA-026A4 | I17: 16
E19: Core adopten محول سيارة | H19: RA-SA-026A5 | I19: 1
E21: Stownd استاند | H21: RA-SA-026A6 | I21: 2
E23: Bosamewb قاعدة الأسطح الناعمة | H23: RA-SA-026A7 | I23: 1
E25: Heods OF Basement رؤوس قاعدة متحرك | H25: RA-SA-026A8 | I25: 2
A32: Last up Date | B32: Taken Over By | D32: Handed Over By | F32: L×W×H | I32: Total | K32: Total Weight | M32: Total Price
A33: =TODAY() -> 46198 | B33: Mishary Al Marzouki | D33: abdulrhman Al-marhabi | F33: Cm | G33: Inch | I33: CBM | J33: CFT | K33: KG | L33: LBS | M33: SAR | N33: USD
F34: 89×35×23 | G34: 35.04×13.78×9.06 | I34: =SUM(89*35*23/1000000) -> 0.071645 | J34: =SUM(35.04*13.78*9.06/1728) -> 2.5316157 | K34: 26 | L34: 41.8 | M34: =SUM(J11) -> 200000 | N34: =SUM(M34/3.75) -> 53333.333

Sheet SA-027
A1: Saudi Search & Rescue team فريق البحث والإنقاذ السعودي | L1: LEGEND
L2: R : RESCUE | N2: RB-SA010-A
L3: B : BRAVO | N3: RB-SA010-A
L4: 010 : BOX NUMBER | N4: RB-SA010-A
L5: A : ITEM NUMBER | N5: RB-SA010-A
A6: RESCUE ALPHA
A7: BOX NUMBER RA-SA-027
A8: S/N | B8: ITEM NUMBER | C8: MAIN ITEM DESCRIPTION | E8: SUB-ITEM | J8: PRICE (SR) | L8: REMARKS
E9: DESCRIPTION | H9: SUB-ITEM NUMBER | I9: QTY
J10: SAR | K10: USD
A11: 1 | B11: RA-SA-027 | C11: خيمة استراحه | I11: 1 | J11: 9640 | K11: =SUM(J11/3.75) -> 2570.6667
A28: Last up Date | B28: Taken Over By | D28: Handed Over By | F28: L×W×H | I28: Total | K28: Total Weight | M28: Total Price
A29: =TODAY() -> 46198 | B29: Mishary Al Marzouki | D29: abdulrhman Al-marhabi | F29: Cm | G29: Inch | I29: CBM | J29: CFT | K29: KG | L29: LBS | M29: SAR | N29: USD
F30: 65×50×120 | G30: 15.75×15.75×40.94 | I30: =SUM(40*40*104/1000000) -> 0.1664 | J30: =SUM(15.75*15.75*40.94/1728) -> 5.8771289 | K30: 82 | L30: =SUM(K30*2.2) -> 180.4 | M30: =SUM(J11) -> 9640 | N30: =SUM(M30/3.75) -> 2570.6667

Sheet Total
A1: ALPHA Summery
A3: # | B3: BOX NUM | D3: TOTAL L×W×H | K3: Weight In KG | M3: PRICE
D4: CM | F4: INCH | I4: CBM | J4: CFT | K4: KG | L4: LBS | M4: SAR | N4: USD
A5: 1 | B5: RA-001 | D5: 130×70×65 | F5: 51.18×27.56×25.59 | I5: 0.5915 | J5: 20.888442 | K5: ='RA-001'!$K$41 -> 140 | L5: =SUM(K5*2.2) -> 308 | M5: 16943 | N5: =SUM(M5/3.75) -> 4518.1333
A6: 2 | B6: RA-002 | D6: 130×70×65 | F6: 51.18×27.56×25.59 | I6: 0.5915 | J6: 20.888442 | K6: ='RA-002'!$K$30 -> 122 | L6: =SUM(K6*2.2) -> 268.4 | M6: 17513 | N6: =SUM(M6/3.75) -> 4670.1333
A7: 3 | B7: RA-003 | D7: 130×70×65 | F7: 51.18×27.56×25.59 | I7: 0.5915 | J7: 20.888442 | K7: ='RA-003'!$K$25 -> 103 | L7: =SUM(K7*2.2) -> 226.6 | M7: 8757 | N7: =SUM(M7/3.75) -> 2335.2
A8: 4 | B8: RA-004 | D8: 130×106×63 | F8: 51.18×27.56×25.59 | I8: 0.5915 | J8: 20.888442 | K8: ='عربة 4'!$K$37 -> 190 | L8: =SUM(K8*2.2) -> 418 | M8: 11466 | N8: =SUM(M8/3.75) -> 3057.6
A9: 5 | B9: RA-005 | D9: 130×70×65 | F9: 51.18×27.56×25.59 | I9: 0.5915 | J9: 20.888442 | K9: ='RA-005'!$K$31 -> 168 | L9: =SUM(K9*2.2) -> 369.6 | M9: 9200 | N9: =SUM(M9/3.75) -> 2453.3333
A10: 6 | B10: RA-006 | D10: 130×70×65 | F10: 51.18×27.56×25.59 | I10: 0.5915 | J10: 20.888442 | K10: ='RA-006'!$K$41 -> 135 | L10: =SUM(K10*2.2) -> 297 | M10: 30063 | N10: =SUM(M10/3.75) -> 8016.8
A11: 7 | B11: RA-007 | D11: 130×70×65 | F11: 51.18×27.56×25.59 | I11: 0.5915 | J11: 20.888442 | K11: ='عربةRA-007'!$K$45 -> 142 | L11: =SUM(K11*2.2) -> 312.4 | M11: 18388 | N11: =SUM(M11/3.75) -> 4903.4667
A12: 8 | B12: RA-008 | D12: 130×70×65 | F12: 51.18×27.56×25.59 | I12: 0.5915 | J12: 20.888442 | K12: ='RA-008'!$K$78 -> 125 | L12: =SUM(K12*2.2) -> 275 | M12: 32354 | N12: =SUM(M12/3.75) -> 8627.7333
A13: 9 | B13: RA-009 | D13: 130×106×63 | F13: 51.18×27.56×25.59 | I13: 0.5915 | J13: 20.888442 | K13: ='عربة 9'!$K$44 -> 154 | L13: =SUM(K13*2.2) -> 338.8 | M13: 8754 | N13: =SUM(M13/3.75) -> 2334.4
A14: 10 | B14: RA-SA-001 | D14: 79×32×49 | F14: 31.1×12.6×19.29 | I14: =SUM(79*32*49/1000000) -> 0.123872 | J14: =SUM(31.1*12.6*19.29/1728) -> 4.3744094 | K14: ='SA-001'!$K$34 -> 16 | L14: =SUM(K14*2.2) -> 35.2 | M14: 1520 | N14: =SUM(M14/3.75) -> 405.33333
A15: 11 | B15: RA-SA-002 | D15: 79×32×49 | F15: 31.1×12.6×19.29 | I15: =SUM(79*32*49/1000000) -> 0.123872 | J15: =SUM(31.1*12.6*19.29/1728) -> 4.3744094 | K15: ='SA-004'!K34 -> 18 | L15: =SUM(K15*2.2) -> 39.6 | M15: 1520 | N15: =SUM(M15/3.75) -> 405.33333
A16: 12 | B16: RA-SA-003 | D16: 79×32×49 | F16: 31.1×12.6×19.29 | I16: =SUM(79*32*49/1000000) -> 0.123872 | J16: =SUM(31.1*12.6*19.29/1728) -> 4.3744094 | K16: ='SA-003'!$K$34 -> 18 | L16: =SUM(K16*2.2) -> 39.6 | M16: 1520 | N16: =SUM(M16/3.75) -> 405.33333
A17: 13 | B17: RA-SA-004 | D17: 79×32×49 | F17: 31.1×12.6×19.29 | I17: =SUM(79*32*49/1000000) -> 0.123872 | J17: =SUM(31.1*12.6*19.29/1728) -> 4.3744094 | K17: ='SA-004'!$K$34 -> 18 | L17: =SUM(K17*2.2) -> 39.6 | M17: 1520 | N17: =SUM(M17/3.75) -> 405.33333
A18: 14 | B18: RA-SA-005 | D18: 86×30×46 | F18: 28.35×19.69×12.6 | I18: =SUM(72*50*32/1000000) -> 0.1152 | J18: =SUM(28.35*19.69*12.6/1728) -> 4.0702922 | K18: ='SA-005'!$K$28 -> 28 | L18: =SUM(K18*2.2) -> 61.6 | M18: 22394 | N18: =SUM(M18/3.75) -> 5971.7333
A19: 15 | B19: RA-SA-006 | D19: 83×29×49 | F19: 32.68×11.42×19.29 | I19: =SUM(83*29*49/1000000) -> 0.117943 | J19: =SUM(32.68*11.42*19.29/1728) -> 4.1661667 | K19: ='SA-006'!$K$28 -> 20 | L19: =SUM(K19*2.2) -> 44 | M19: 38880 | N19: =SUM(M19/3.75) -> 10368
A20: 16 | B20: RA-SA-007 | D20: 78×27×47 | F20: 30.71×10.63×18.5 | I20: =SUM(78*27*47/1000000) -> 0.098982 | J20: =SUM(30.71*10.63*18.5/1728) -> 3.4949508 | K20: ='SA-007'!$K$31 -> 19 | L20: =SUM(K20*2.2) -> 41.8 | M20: 26400 | N20: =SUM(M20/3.75) -> 7040
A21: 17 | B21: RA-SA-008 | D21: 88×31×42 | F21: 34.65×12.2×16.54 | I21: =SUM(88*31*42/1000000) -> 0.114576 | J21: =SUM(34.65*12.2*16.54/1728) -> 4.0462698 | K21: ='SA-008'!$K$30 -> 12 | L21: =SUM(K21*2.2) -> 26.4 | M21: 22600 | N21: =SUM(M21/3.75) -> 6026.6667
A22: 18 | B22: RA-SA-009 | D22: 72×50×32 | F22: 28.35×19.69×12.6 | I22: =SUM(72*50*32/1000000) -> 0.1152 | J22: =SUM(28.35*19.69*12.6/1728) -> 4.0702922 | K22: ='SA-009'!$K$24 -> 26 | L22: =SUM(K22*2.2) -> 57.2 | M22: 21570 | N22: =SUM(M22/3.75) -> 5752
A23: 19 | B23: RA-SA-010 | D23: 40×40×104 | F23: 15.75×15.75×40.94 | I23: =SUM(40*40*104/1000000) -> 0.1664 | J23: =SUM(15.75*15.75*40.94/1728) -> 5.8771289 | K23: ='SA-0010'!$K$33 -> 43 | L23: =SUM(K23*2.2) -> 94.6 | M23: 9640 | N23: =SUM(M23/3.75) -> 2570.6667
A24: 20 | B24: RA-SA-011 | D24: 123×36×27 | F24: 48.43×14.17×10.36 | I24: =SUM(123*36*27/1000000) -> 0.119556 | J24: =SUM(48.43*14.17*10.36/1728) -> 4.1143415 | K24: ='SA-0011'!K21 -> 24 | L24: =SUM(K24*2.2) -> 52.8 | M24: ='SA-0011'!M21 -> 13425 | N24: =SUM(M24/3.75) -> 3580
A25: 21 | B25: RA-SA-012 | D25: 25×25×60 | F25: 9.84×9.84×23.62 | I25: 0.0375 | J25: =SUM(9.84*9.84*23.62/1728) -> 1.3235073 | K25: ='SA-0012'!$K$30 -> 3 | L25: 13.2 | M25: 100 | N25: =SUM(M25/3.75) -> 26.666667
A26: 22 | B26: RA-SA-013 | D26: 56×34×23 | F26: 22.05×13.39×9.06 | I26: =SUM(56*34*23/1000000) -> 0.043792 | J26: =SUM(22.05*13.39*9.06/1728) -> 1.5480095 | K26: ='SA-0013'!$K$30 -> 64 | L26: =SUM(K26*2.2) -> 140.8 | M26: 11294 | N26: =SUM(M26/3.75) -> 3011.7333
A27: 23 | B27: RA-SA-014 | D27: 65×51×23 | F27: 25.59×20.08×9.06 | I27: =SUM(65*51*23/1000000) -> 0.076245 | J27: =SUM(25.59*20.08*9.06/1728) -> 2.6941294 | K27: ='SA-0014'!$K$23 -> 20 | L27: =SUM(K27*2.2) -> 44 | M27: 149000 | N27: =SUM(M27/3.75) -> 39733.333
A28: 24 | B28: RA-SA-015 | D28: 121×39×16 | F28: 47.64×15.35×6.3 | I28: =SUM(121*39*16/1000000) -> 0.075504 | J28: =SUM(47.64*15.35*6.3/1728) -> 2.6661031 | K28: ='SA-0015'!$K$24 -> 16 | L28: =SUM(K28*2.2) -> 35.2 | M28: 12000 | N28: =SUM(M28/3.75) -> 3200
A29: 25 | B29: RA-SA-016 | D29: 89×35×23 | F29: 35.04×13.78×9.06 | I29: =SUM(89*35*23/1000000) -> 0.071645 | J29: =SUM(35.04*13.78*9.06/1728) -> 2.5316157 | K29: ='SA-0016'!$K$34 -> 25 | L29: 41.8 | M29: 3750 | N29: =SUM(M29/3.75) -> 1000
A30: 26 | B30: RA-SA-018 | D30: 88×53×33 | F30: 34.65×20.87×12.99 | I30: =SUM(88*53*33/1000000) -> 0.153912 | J30: =SUM(34.65*20.87*12.99/1728) -> 5.4361459 | K30: ='SA-0018'!$K$36 -> 30 | L30: =SUM(K30*2.2) -> 66 | M30: 4589 | N30: =SUM(M30/3.75) -> 1223.7333
